Workbook

Sheet 1) ลิงก์วันปฐมนิเทศ
A1: รายการหัวข้อ youtube ที่ใช้ในวันปฐมนิเทศ (เรียงตามลำดับการใช้งาน)
A2: ลำดับ | B2: วีดิทัศน์ใช้ในวันปฐมนิเทศ | C2: ลิงก์ (Link) | D2: ความยาว (นาที)
A3: 1 | B3: เพลงอรุณทอแสง | C3: https://youtu.be/_Zsr-xXAcZ8 | D3: 4:10
A4: 2 | B4: คำกล่าวบูชาพระรัตนตรัย | C4: https://youtu.be/c29VxS0RgPg | D4: 1:36
A5: 3 | B5: พิธีมอบตัวเป็นศิษย์ | C5: https://youtu.be/h0RaGmNPCT0 | D5: 6:57
A6: 4 | B6: คำสัตย์ปฏิญาณ | C6: https://youtu.be/JFSEwxvw_PA | D6: 1:31
A7: 5 | B7: อัตชีวประวัติสมเด็จพระญาณวชิโรดม วิริยังค์ สิรินฺธโร | C7: https://youtu.be/_Ca7x0NEAxs | D7: 25:27
A8: 6 | B8: สัมโมทนียกถา | C8: https://youtu.be/hNTNAxVW-5o | D8: 26:46
A9: 7 | B9: พิธีเปิดหลักสูตรวิทันตสาสมาธิ | C9: https://youtu.be/TiNPUIDwuSE | D9: 27:13
A10: 8 | B10: ระเบียบปฏิบัติการเรียนสมาธิออนไลน์ | C10: https://youtu.be/NRgY-1rIWtM | D10: 03:20
A11: 9 | B11: วิธีเดินจงกรม | C11: https://youtu.be/HbI_l-zx9Sg | D11: 4:31
A12: 10 | B12: วิธีนั่งสมาธิ | C12: https://youtu.be/hZTUNntTkBY | D12: 3:52
A13: 11 | B13: นาฬิกาจับเวลา | C13: https://sumana.org/clock/?openExternalBrowser=1
A14: 12 | B14: บทสวดอธิษฐานก่อนการเดินจงกรม | C14: https://youtu.be/o0B6212q8wo | D14: 0:18
A15: 13 | B15: บทสวดแผ่เมตตาหลังการเดินจงกรม | C15: https://youtu.be/0_DOyGbAPfo | D15: 0:21
A16: 14 | B16: บทสวดอธิษฐานก่อนการนั่งสมาธิ | C16: https://youtu.be/AM0o2bywjaM | D16: 0:54
A17: 15 | B17: บทสวดแผ่เมตตาหลังการนั่งสมาธิ | C17: https://youtu.be/zQkscnSYO10 | D17: 1:16
A18: 16 | B18: วิริยังคมหาเถโรวาท | C18: https://youtu.be/ToLV7T9aZoc | D18: 0:30

Sheet 2)ลิงก์เรียนประจำวัน
A1: ลิงก์สำหรับโพสต์ประจำวัน
A2: ลำดับ | B2: กิจกรรม | C2: เวลาความยาวลิงก์ (นาที) | D2: ข้อความพิมพ์หัวลิงก์ | E2: Link กิจกรรม | F2: หมายเหตุ
A3: 1 | B3: ระเบียบปฏิบัติการเรียนสมาธิออนไลน์ | C3: 3.19 | D3: ระเบียบปฏิบัติ การเรียนหลักสูตรวิทันตสาสมาธิออนไลน์ | E3: https://youtu.be/NRgY-1rIWtM | F3: โพสต์เพียงครั้งเดียว (ไม่ต้องลบออกจากห้องเรียน) และไม่ต้องโพสต์ใหม่ทุกวัน
A4: 2 | B4: นำเข้าสู่บทเรียน | C4: 2.54 | D4: เรียนเชิญนักศึกษาเข้าสู่บทเรียน ร่วมบูชาพระรัตนตรัย และกล่าวคำสัตย์ปฏิญาณโดยพร้อมเพรียงกัน | E4: https://youtu.be/ienVuHBQMxQ | F4: -
A5: 3 | B5: ปฏิบัติเดินจงกรม 30 นาที | C5: 31.12 | D5: ขอเชิญนักศึกษาทุกท่านปฏิบัติเดินจงกรม เป็นเวลา 30 นาที | E5: https://youtu.be/jHQ_63bROqY | F5: -
A6: 4 | B6: ปฏิบัตินั่งสมาธิ 30 นาที | C6: 32.32 | D6: ขอเชิญนักศึกษาทุกท่านปฏิบัตินั่งสมาธิ เป็นเวลา 30 นาที | E6: https://youtu.be/hiZ16DCP1eI | F6: -
A7: 5 | B7: ช่วงท้ายบทเรียน-บูชาพระรัตนตรัย | C7: 1.52 | D7: ขอเชิญนักศึกษาทุกท่านร่วมบูชาพระรัตนตรัย โดยพร้อมเพรียงกัน | E7: https://youtu.be/viTRlM3Xme4 | F7: -

Sheet 3) ลิงก์วันเรียนปกติเทอม 1
A1: ตารางเรียนหลักสูตรวิทันตสาสมาธิ online (เทอม 1)
A2: สาขาที่เปิดเรียน พฤศจิกายน 2567 เรียนวันจันทร์-ศุกร์ เวลา 18.00 - 20.00 น.
A3: เทอม 1 เริ่มวันที่ 3 พฤศจิกายน 2567 - วันที่ 30 มกราคม 2568
A5: ครั้งที่ | B5: วดป | C5: เวลา | D5: หัวข้อวิชา | E5: เวลาฟังบรรยาย พระอาจารย์ | F5: Link เทปพระอาจารย์หลวงพ่อ | G5: เวลาฟังทบทวนการบรรยาย (อาจารย์) | H5: Link อาจารย์ ทบทวนการบรรยาย | I5: อาจารย์บรรยาย | J5: หมายเหตุ
A6: 1 | B6: 45599 | C6: 18.00 - 20.00 น. | D6: ปฐมนิเทศ(มอบตัวเป็นศิษย์/แนะนำระเบียบปฏิบัตินการเรียน | F6: ลิงก์อยู่ใน Sheet ที่ 1) ลิงก์วันปฐมนิเทศ | J6: ที่ห้องเรียนออนไลน์ หรือสาขา
D7: สัมโมทนียกถา /รับชมประวัติของสมเด็จพระญาณวชิโรดม
D8: พิธีเปิด/ปฏิบัติเดินจงกรม-นั่งสมาธิ)
A9: 2 | B9: 45600 | C9: 18.00 - 20.00 น. | D9: จุดประสงค์ของการทำสมาธิ | E9: 23.31 | F9: https://youtu.be/1Z1ezwQ1Bhs | G9: 13:31 | H9: https://youtu.be/Yp49Ssq9BGc | I9: ดร.บวรศักดิ์อุวรรณโณ
A10: 3 | B10: 45601 | C10: 18.00 - 20.00 น. | D10: 1.1.01 อิริยาบถ ยืน-เดิน-นั่ง-นอน | E10: 28.48 | F10: https://youtu.be/jsUwwJCnKpc | G10: 13:09 | H10: https://youtu.be/xfg51X1HfVs | I10: อ.เรณุกา พันทวีศักดิ์
A11: 4 | B11: 45602 | C11: 18.00 - 20.00 น. | D11: 1.1.02 อาการ-กิริยา | E11: 40.31 | F11: https://youtu.be/z4My3WB6hV8 | G11: 15:20 | H11: https://youtu.be/6mBUyIBMe7g | I11: อ.แสงอรุณ วัฒนวงศ์
A12: 5 | B12: 45603 | C12: 18.00 - 20.00 น. | D12: 1.1.03 สถานที่-บริเวณ | E12: 43.51 | F12: https://youtu.be/KAuyqG4_6Nc | G12: 12:33 | H12: https://youtu.be/TdK737oKbjU | I12: อ.ศรีวิมล ฉัตรจุฑามาส
A13: 6 | B13: 45604 | C13: 18.00 - 20.00 น. | D13: 1.1.04 ชุมชน-ป่าไม้-ภูเขา | E13: 44.39 | F13: https://youtu.be/FlJ40cuS3_U | G13: 14:31 | H13: https://youtu.be/hdeiuhdcYUg | I13: ดร.สิริกร สุขเกษม
A14: 7 | B14: 45607 | C14: 18.00 - 20.00 น. | D14: 1.1.05 อากาศ หนาว- ร้อน | E14: 35.13 | F14: https://youtu.be/GkvZlqGT1YQ | G14: 14:18 | H14: https://youtu.be/y8GmNfHdEkw | I14: รศ.ธิติ รักชาติ
A15: 8 | B15: 45608 | C15: 18.00 - 20.00 น. | D15: 1.1.06 เวลา | E15: 39.1 | F15: https://youtu.be/npZS9SMXZfY | G15: 17:19 | H15: https://youtu.be/tWbW32oQNts | I15: อ.พรรณี จารุสมบัติ
A16: 9 | B16: 45609 | C16: 18.00 - 20.00 น. | D16: 1.2.01 ความตั้งใจ | E16: 31.51 | F16: https://youtu.be/rGBrob_39Zs | G16: 13:44 | H16: https://youtu.be/DnHVtsJ8xVw | I16: อ.วรรณา ลิ่มพานิชย์
A17: 10 | B17: 45610 | C17: 18.00 - 20.00 น. | D17: 1.2.02 ความวางใจ | E17: 44.44 | F17: https://youtu.be/vwrfLItlUM4 | G17: 12:09 | H17: https://youtu.be/3oTBJw_TU7o | I17: ผศ.ดร.ปฐมพงษ์ โพธิ์ประสิทธิ์นันท์
A18: 11 | B18: 45611 | C18: 18.00 - 20.00 น. | D18: 1.2.03 การบริกรรม | E18: 37.21 | F18: https://youtu.be/bYbxsqiIdVs | G18: 18:13 | H18: https://youtu.be/pe045Lo1g9U | I18: ดร.ดาวน้อย สุทธินิภาพันธ์
A19: 12 | B19: 45614 | C19: 18.00 - 20.00 น. | D19: 1.2.04 เริ่มต้นการกำหนด | E19: 44.02 | F19: https://youtu.be/1hv8TXyb0h4 | G19: 15:17 | H19: https://youtu.be/tjOX936dv5s | I19: อ.สุดารักษ์ ยิ่งสกุล
A20: 13 | B20: 45615 | C20: 18.00 - 20.00 น. | D20: 1.2.05 เกี่ยวกับลมหายใจ | E20: 44.53 | F20: https://youtu.be/nQ__vzO-aU8 | G20: 15:52 | H20: https://youtu.be/JS0SRoJXQuw | I20: รศ.ภณิดา มาประเสริฐ
... A31: 24 | B31: 45630 | C31: 18.00 - 20.00 น. | D31: 1.3.08 การวัดผลของการบริกรรม | E31: 44.05 | F31: https://youtu.be/8ss4Z8pQMoQ | G31: 12:41 | H31: https://youtu.be/71I2oibEBvQ | I31: อ.สาธิตา ชูติกาญจน์
B32: 45631 | C32: หยุดเรียน วันคล้ายวันเฉลิมฯ รัชกาลที่ 9 (วันพ่อแห่งชาติ)
A33: 25 | B33: 45632 | C33: 18.00 - 20.00 น. | D33: 1.4.01 ความเจ็บปวด เมื่อย เหนื่อย หิว | E33: 42.38 | F33: https://youtu.be/qbCMcBXWpg4 | G33: 13:21 | H33: https://youtu.be/TYSh3tO586s | I33: อ.ประพีร์ บุรี
A34: 26 | B34: 45635 | C34: 18.00 - 20.00 น. | D34: 1.4.02 ความปริวิตก | E34: 41.1 | F34: https://youtu.be/aC051-TDORA | G34: 13:12 | H34: https://youtu.be/XIcqWdLKSCg | I34: ดร.ธเนศ วีระศิริ
B35: 45636 | C35: หยุดเรียน วันรัฐธรรมนูญ
A36: 27 | B36: 45637 | C36: 18.00 - 20.00 น. | D36: 1.4.03 ความกระวนกระวาย | E36: 43.49 | F36: https://youtu.be/JfWIXtraNFA | G36: 13:43 | H36: https://youtu.be/uNg96_LTBUY | I36: ดร.ธีรวัฒนา ภาระมาตย์
A37: 28 | B37: 45638 | C37: 18.00 - 20.00 น. | D37: 1.4.04 ความหงุดหงิด | E37: 44 | F37: https://youtu.be/h1ENOO4Pe1s | G37: 15:12 | H37: https://youtu.be/EOZGI0nqMMo | I37: อ.จุไร วรศักดิ์โยธิน
A38: 29 | B38: 45639 | C38: 18.00 - 20.00 น. | D38: 1.4.05 อาการกิริยาเจ็บคันโดยไม่มีเหตุผล | E38: 42.31 | F38: https://youtu.be/d1hP4lDc8dQ | G38: 11:42 | H38: https://youtu.be/ns6yjsLcxso | I38: อ.ปัทมาภรณ์ มิกานนท์
A39: 30 | B39: 45641 | C39: กิจกรรมสัมพันธ์ ครั้งที่ 1 | F39: คำกล่าวเปิดกิจกรรมสัมพันธ์ ครั้งที่ 1 | G39: 0.64652778 | H39: https://youtu.be/625LLtsHaXA | I39: ดร.ดาวน้อย สุทธินิภาพันธ์
F40: เก้ามหามงคล วัดธรรมมงคล | G40: 32:21 | H40: https://youtu.be/b699LdzsQlA
A41: 31 | B41: 45642 | C41: 18.00 - 20.00 น. | D41: 1.4.06 ความลังเลสงสัย | E41: 44.01 | F41: https://youtu.be/H9t_ONFyUuQ | G41: 15:26 | H41: https://youtu.be/Tyv7h9rqu4Q | I41: แพทย์หญิงปณดา อัศวเคนทร์กุล
A42: 32 | B42: 45643 | C42: 18.00 - 20.00 น. | D42: 1.4.07 ความโลภอยากได้เร็ว | E42: 42.4 | F42: https://youtu.be/hay-fJ7MIA8 | G42: 15:12 | H42: https://youtu.be/rE0FXfQCEDI | I42: อ.ทรงศิริ จุมพล
A43: 33 | B43: 45644 | C43: 18.00 - 20.00 น. | D43: 2.1.01 ลักษณะของสมาธิ | E43: 44.35 | F43: https://youtu.be/99ZC6F5S_34 | G43: 15:49 | H43: https://youtu.be/kUHJEkjdKwc | I43: ผศ.พรทิพย์ รักชาติ
A44: 34 | B44: 45645 | C44: 18.00 - 20.00 น. | D44: 2.1.02 ขั้นตอนของสมาธิ | E44: 41.44 | F44: https://youtu.be/Y3RdrgsiSVA | G44: 15:20 | H44: https://youtu.be/1YOtfA81qHM | I44: อ.วรเดช กล่อมจันทร์
A45: 35 | B45: 45646 | C45: 18.00 - 20.00 น. | D45: 2.1.03 คุณสมบัติของสมาธิ | E45: 43.21 | F45: https://youtu.be/qIYl6clE2Nc | G45: 16:28 | H45: https://youtu.be/bgrTH1nwJcg | I45: อ.สมพร สะราคำ
A46: 36 | B46: 45649 | C46: 18.00 - 20.00 น. | D46: 2.1.04 การวัดผลของสมาธิ | E46: 43.33 | F46: https://youtu.be/IH4TpMCWJoU | G46: 13:24 | H46: https://youtu.be/hj99idjNrUk | I46: อ.อุมาลี อยู่นันท์
A47: 37 | B47: 45650 | C47: 18.00 - 20.00 น. | D47: 2.1.05 ประโยชน์ของสมาธิ | E47: 33.15 | F47: https://youtu.be/jpLg_sVBYbM | G47: 15.40 | H47: https://youtu.be/oFI5PJXnqgI | I47: รศ.กัลยาภรณ์ ปานมะเริง
A48: 38 | B48: 45651 | C48: 18.00 - 20.00 น. | D48: 2.1.06 สมาธิตื้น | E48: 17.35 | F48: https://youtu.be/EmlFr2NobcA | G48: 15:31 | H48: https://youtu.be/ZUdjYcX2qDI | I48: อ.วัชรี วัฒนาสุทธิวงศ์
A49: 39 | B49: 45652 | C49: 18.00 - 20.00 น. | D49: 2.1.07 สมาธิลึก | E49: 35.26 | F49: https://youtu.be/_zgPqgxxgn8 | G49: 13:27 | H49: https://youtu.be/X7-5nZBVSME | I49: อ.วรภา องอาจ
A50: 40 | B50: 45653 | C50: 18.00 - 20.00 น. | D50: 2.1.08 อาการของสมาธิ | E50: 43.22 | F50: https://youtu.be/tA44TijbMJk | G50: 15:58 | H50: https://youtu.be/0C9UHvKPonI | I50: อ.จินตนา ล้ำเลิศวิทยา
B51: ส. 28 ธ.ค. 67 - พฤ. 2 ม.ค. 68 | D51: หยุดเรียน เทศกาลวันปีใหม่
...

Sheet 4) ลิงก์วันเรียนเสริมเทอม 1
A1: ตารางเรียนหลักสูตรวิทันตสาสมาธิ online (เสริมเทอม 1)
A2: สาขาที่เปิดเรียน พฤศจิกายน 2567 เรียนวันจันทร์-ศุกร์ เวลา 18.00 - 20.00 น.
A5: ครั้งที่ | B5: วดป | C5: เวลา | D5: หัวข้อวิชา | E5: เวลาฟังบรรยาย พระอาจารย์ | F5: Link เทปพระอาจารย์หลวงพ่อ | G5: เวลาฟังทบทวนการบรรยาย (อาจารย์) | H5: Link อาจารย์ ทบทวนการบรรยาย | I5: อาจารย์บรรยาย
A6: 1 | B6: 45612 | C6: 18.00 - 20.00 น. | D6: จุดประสงค์ของการทำสมาธิ | E6: 23.31 | F6: https://youtu.be/1Z1ezwQ1Bhs | G6: 13:31 | H6: https://youtu.be/Yp49Ssq9BGc | I6: ดร.บวรศักดิ์อุวรรณโณ
A7: 2 | B7: 45613 | C7: 18.00 - 20.00 น. | D7: 1.1.01 อิริยาบถ ยืน-เดิน-นั่ง-นอน | E7: 28.48 | F7: https://youtu.be/jsUwwJCnKpc | G7: 13:09 | H7: https://youtu.be/xfg51X1HfVs | I7: อ.เรณุกา พันทวีศักดิ์
A8: 3 | B8: 45619 | C8: 18.00 - 20.00 น. | D8: 1.1.02 อาการ-กิริยา | E8: 40.31 | F8: https://youtu.be/z4My3WB6hV8 | G8: 15:20 | H8: https://youtu.be/6mBUyIBMe7g | I8: อ.แสงอรุณ วัฒนวงศ์
A9: 4 | B9: 45620 | C9: 18.00 - 20.00 น. | D9: 1.2.03 การบริกรรม | E9: 37.21 | F9: https://youtu.be/bYbxsqiIdVs | G9: 18:13 | H9: https://youtu.be/pe045Lo1g9U | I9: ดร.ดาวน้อย สุทธินิภาพันธ์
A10: 5 | B10: 45626 | C10: 18.00 - 20.00 น. | D10: 1.2.04 เริ่มต้นการกำหนด | E10: 44.02 | F10: https://youtu.be/1hv8TXyb0h4 | G10: 15:17 | H10: https://youtu.be/tjOX936dv5s | I10: อ.สุดารักษ์ ยิ่งสกุล
A11: 6 | B11: 45627 | C11: 18.00 - 20.00 น. | D11: 1.2.07 เกี่ยวกับอารมณ์ | E11: 42.13 | F11: https://youtu.be/9Pty9jRw2KA | G11: 14.55 | H11: https://youtu.be/bt_IMG3avnU | I11: อ.สิทธิพล วงษ์ดนตรี
A12: 7 | B12: 45633 | C12: 18.00 - 20.00 น. | D12: 1.3.01 การบริกรรม คือนึกพุทโธ ฯลฯ | E12: 40.38 | F12: https://youtu.be/2DM0hJFJ-_o | G12: 14:42 | H12: https://youtu.be/sbOOlxrki44 | I12: อ.พีระศักดิ์ ขุนอินทร์
A13: 8 | B13: 45634 | C13: 18.00 - 20.00 น. | D13: 1.3.04 การไม่บริกรรม กำหนดความหยุด | E13: 44.05 | F13: https://youtu.be/a-S8yN8LrFo | G13: 14:55 | H13: https://youtu.be/hU7B_EAQQNE | I13: อ.อุสา ธีรนิพัทธ์
A14: 9 | B14: 45640 | C14: 18.00 - 20.00 น. | D14: 1.3.05 การผ่อนลมหายใจในขณะกำหนดความหยุด | E14: 42.32 | F14: https://youtu.be/dlpztHM46CM | G14: 14:37 | H14: https://youtu.be/U48PORHqPJE | I14: อ.นริศ พุ่มดนตรี
A15: 10 | B15: 45647 | C15: 18.00 - 20.00 น. | D15: 1.3.07 การวางจิตขณะบริกรรม | E15: 41.34 | F15: https://youtu.be/yGpxWqtBsz4 | G15: 14:33 | H15: https://youtu.be/j_9UFJb7ARQ | I15: อ.รัตติยา นิติพานิช
A16: 11 | B16: 45648 | C16: 18.00 - 20.00 น. | D16: 1.4.01 ความเจ็บปวด เมื่อย เหนื่อย หิว | E16: 42.38 | F16: https://youtu.be/qbCMcBXWpg4 | G16: 13:21 | H16: https://youtu.be/TYSh3tO586s | I16: อ.ประพีร์ บุรี
A17: 12 | B17: 45668 | C17: 18.00 - 20.00 น. | D17: 1.4.07 ความโลภอยากได้เร็ว | E17: 42.4 | F17: https://youtu.be/hay-fJ7MIA8 | G17: 15:12 | H17: https://youtu.be/rE0FXfQCEDI | I17: อ.ทรงศิริ จุมพล
... A19: 14 | B19: 45675 | C19: 18.00 - 20.00 น. | D19: 2.1.02 ขั้นตอนของสมาธิ | E19: 41.44 | F19: https://youtu.be/Y3RdrgsiSVA | G19: 15:20 | H19: https://youtu.be/1YOtfA81qHM | I19: อ.วรเดช กล่อมจันทร์

Sheet 5.)ตัวอย่างลำดับการโพสเรียนปกติ
A1: ส่วนใส่ข้อมูล
A2: วันที่ | B2: 45609 | C2: ใส่วันที่เป็นคริสตศักราช
A3: สาขา | B3: 8
A4: ชื่อสาขา | B4: อาคารไอทาวเวอร์
A5: Link google form บันทึกผลการเรียนของสาขา | B5: https://forms.gle/VDZgNpakb9Pxg2n
A7: ข้อมูลอ้างอิงณวันที่เลือก
A8: วันที่ | B8: ="วัน"&TEXT($B$2,"[$-B000041E]dddd")&"ที่ "&DAY($B$2)&" "&TEXT($B$2,"[$-B000041E]mmm")&" "&RIGHT((YEAR($B$2)+543), 2) -> วันพุธที่ 13 พ.ย. 67
A9: หัวข้อวิชา | B9: {=TRIM(INDEX('3) ลิงก์วันเรียนปกติเทอม 1'!$D:$D,MATCH($B$2,'3) ลิงก์วันเรียนปกติเทอม 1'!$B:$B,0)))} -> 1.2.01 ความตั้งใจ
A10: เลขหัวข้อ | B10: =TRIM(LEFT(B9, SEARCH(" ", TRIM(B9)) )) -> 1.2.01
A11: เวลาฟังบรรยาย พระอาจารย์ | B11: {=TRIM(INDEX('3) ลิงก์วันเรียนปกติเทอม 1'!$E:$E,MATCH($B$2,'3) ลิงก์วันเรียนปกติเทอม 1'!$B:$B,0)))} -> 31.51 | C11: นาที
A12: Link เทปพระอาจารย์หลวงพ่อ | B12: {=TRIM(INDEX('3) ลิงก์วันเรียนปกติเทอม 1'!$F:$F,MATCH($B$2,'3) ลิงก์วันเรียนปกติเทอม 1'!$B:$B,0)))} -> https://youtu.be/rGBrob_39Zs
A13: เวลาฟังทบทวนการบรรยาย (อาจารย์) | B13: {=TRIM(INDEX('3) ลิงก์วันเรียนปกติเทอม 1'!$G:$G,MATCH($B$2,'3) ลิงก์วันเรียนปกติเทอม 1'!$B:$B,0)))} -> 13:44 | C13: นาที
A14: Link อาจารย์ ทบทวนการบรรยาย | B14: {=TRIM(INDEX('3) ลิงก์วันเรียนปกติเทอม 1'!$H:$H,MATCH($B$2,'3) ลิงก์วันเรียนปกติเทอม 1'!$B:$B,0)))} -> https://youtu.be/DnHVtsJ8xVw
A15: อาจารย์บรรยาย | B15: {=TRIM(INDEX('3) ลิงก์วันเรียนปกติเทอม 1'!$I:$I,MATCH($B$2,'3) ลิงก์วันเรียนปกติเทอม 1'!$B:$B,0)))} -> อ.วรรณา ลิ่มพานิชย์
A17: ลำดับ | B17: กิจกรรม | C17: หมายเหตุ | D17: ข้อมูลสำหรับคำนวณ | E17: เวลา | F17: ข้อความ รูปโพสต์ในห้องเตรียมข้อมูลกลาง | G17: Download รูป/link | H17: preview link
A18: 1 | B18: หัวข้อวันที่เตรียมข้อมูลโดยสาขา | D18: ="จัดเตรียมข้อมูล"&CHAR(10) &B8 & CHAR(10) &B9 -> จัดเตรียมข้อมูล วันพุธที่ 13 พ.ย. 67 1.2.01 ความตั้งใจ | E18: - | F18: =D18 -> จัดเตรียมข้อมูล วันพุธที่ 13 พ.ย. 67 1.2.01 ความตั้งใจ
A19: =A18+1 -> 2 | B19: * เวลา 08.00 น. โพสต์ | D19: * เวลา 08.00 น. โพสต์ | E19: 08.00 | F19: =D19 -> * เวลา 08.00 น. โพสต์
A20: =A19+1 -> 3 | B20: ระเบียบปฏิบัติการเรียนสมาธิออนไลน์ | C20: โพสต์เพียงครั้งเดียว (ไม่ต้องลบออกจากห้องเรียน) และไม่ต้องโพสต์ใหม่ทุกวัน | D20: ระเบียบปฏิบัติ การเรียนหลักสูตรวิทันตสาสมาธิ (ออนไลน์) https://youtu.be/NRgY-1rIWtM | E20: - | F20: =D20 -> ระเบียบปฏิบัติ การเรียนหลักสูตรวิทันตสาสมาธิ (ออนไลน์) https://youtu.be/NRgY-1rIWtM | G20: =HYPERLINK("https://youtu.be/NRgY-1rIWtM") -> https://youtu.be/NRgY-1rIWtM | H20: #NAME?
A21: =A20+1 -> 4 | B21: * เวลา 17.45 น. โพสต์ | D21: * เวลา 17.45 น. โพสต์ | E21: 17.45 | F21: =D21 -> * เวลา 17.45 น. โพสต์
A22: =A21+1 -> 5 | B22: ขอเชิญนักศึกษาเตรียมความพร้อมเข้าสู่บทเรียน | C22: สไลด์เรียนประจำวัน | D22: เรียนประจำวัน-Slide1.JPG | E22: 17.45 | F22: #NAME? | G22: =HYPERLINK(VLOOKUP(D22,linkเรียนประจำวัน!E:G,3,FALSE)) -> https://drive.google.com/file/d/1qEFjPE12L0OST-IfMwE0TqLEAok_Gj_Y/view?usp=drivesdk
A23: =A22+1 -> 6 | B23: คำเตือน เรื่องการละเมิดลิขสิทธิ์ | C23: สไลด์เรียนประจำวัน | D23: เรียนประจำวัน-Slide2.JPG | E23: 17.45 | F23: #NAME? | G23: =HYPERLINK(VLOOKUP(D23,linkเรียนประจำวัน!E:G,3,FALSE)) -> https://drive.google.com/file/d/1fRZwcyO1bupTd_ZP73mlu2IJOa5sl0lO/view?usp=drivesdk
A24: =A23+1 -> 7 | B24: หัวข้อที่เรียน | C24: สไลด์เรียนประจำวัน | D24: =TRIM($B$10)&"-Slide1.JPG" -> 1.2.01-Slide1.JPG | E24: 17.45 | F24: #NAME? | G24: =HYPERLINK(VLOOKUP(D24,linkรูปหัวข้อเรียน!E:G,3,FALSE)) -> https://drive.google.com/file/d/1gw7fyIBKY2FgjMLA8IouQSlH3vAkMkHs/view?usp=drivesdk
A25: =A24+1 -> 8 | B25: เพลงอรุณทอแสง | C25: สไลด์เรียนประจำวัน | D25: เพลงอรุณทอแสง https://youtu.be/_Zsr-xXAcZ8 | E25: 17.45 | F25: เพลงอรุณทอแสง https://youtu.be/_Zsr-xXAcZ8 | G25: https://youtu.be/_Zsr-xXAcZ8 | H25: #NAME?
A26: =A25+1 -> 9 | B26: * เวลา 18.00 น. โพสต์ | D26: * เวลา 18.00 น. โพสต์ | F26: =D26 -> * เวลา 18.00 น. โพสต์
A27: =A26+1 -> 10 | B27: เรียนเชิญนักศึกษาเข้าสู่บทเรียน ร่วมบูชาพระรัตนตรัย และกล่าวคำสัตย์ปฏิญาณโดยพร้อมเพรียงกัน | C27: นำเข้าสู่บทเรียน | D27: เรียนเชิญนักศึกษาเข้าสู่บทเรียน ร่วมบูชาพระรัตนตรัย และกล่าวคำสัตย์ปฏิญาณโดยพร้อมเพรียงกัน https://youtu.be/ienVuHBQMxQ | E27: ='2)ลิงก์เรียนประจำวัน'!C4 -> 2.54 | F27: =D27 -> เรียนเชิญนักศึกษาเข้าสู่บทเรียน ร่วมบูชาพระรัตนตรัย และกล่าวคำสัตย์ปฏิญาณโดยพร้อมเพรียงกัน https://youtu.be/ienVuHBQMxQ | G27: https://youtu.be/ienVuHBQMxQ | H27: #NAME?
A28: =A27+1 -> 11 | B28: ="* เวลา "&E28&" น. โพสต์" -> * เวลา 18.05 น. โพสต์ | D28: ="* เวลา "&E28&" น. โพสต์" -> * เวลา 18.05 น. โพสต์ | E28: 18.05 | F28: =D28 -> * เวลา 18.05 น. โพสต์
A29: =A28+1 -> 12 | B29: =D29 -> วันพุธที่ 13 พ.ย. 67 หัวข้อ 1.2.01 ความตั้งใจ เทปบรรยาย https://youtu.be/rGBrob_39Zs | D29: =$B$8& CHAR(10) &"หัวข้อ " & $B$9 & CHAR(10) &"เทปบรรยาย" &CHAR(10) &CHAR(10) &B12 -> วันพุธที่ 13 พ.ย. 67 หัวข้อ 1.2.01 ความตั้งใจ เทปบรรยาย https://youtu.be/rGBrob_39Zs | E29: =TEXT(B11,"00.00") -> 31.51 | F29: =D29 -> วันพุธที่ 13 พ.ย. 67 หัวข้อ 1.2.01 ความตั้งใจ เทปบรรยาย https://youtu.be/rGBrob_39Zs | G29: =HYPERLINK(B12) -> https://youtu.be/rGBrob_39Zs | H29: #NAME?
A30: =A29+1 -> 13 | B30: =D30 -> * เวลา 18:37 น. โพสต์ | D30: ="* เวลา "&TEXT(E30,"hh:mm")&" น. โพสต์" -> * เวลา 18:37 น. โพสต์ | E30: =TIME(LEFT(E28,2),RIGHT(E28,2),0)+IF(INT(RIGHT(E29,2))>0,TIME(0,LEFT(E29,2)+1,0),TIME(0,LEFT(E29,2),0)) -> 0.77569444 | F30: =D30 -> * เวลา 18:37 น. โพสต์
A31: =A29+1 -> 13 | B31: กราบนมัสการพระอาจารย์ | C31: สไลด์เรียนประจำวัน | D31: เรียนประจำวัน-Slide4.JPG | E31: =E30 -> 0.77569444 | F31: #NAME? | G31: =HYPERLINK(VLOOKUP(D31,linkเรียนประจำวัน!E:G,3,FALSE)) -> https://drive.google.com/file/d/1OJ5AltlO515XLHsEvLzcZqzf5DJzpgmd/view?usp=drivesdk
A32: =A31+1 -> 14 | B32: ทบทวนการบรรยาย | D32: =TRIM($B$10)&"-Slide2.JPG" -> 1.2.01-Slide2.JPG | E32: =E31 -> 0.77569444 | F32: #NAME? | G32: =HYPERLINK(VLOOKUP(D32,linkรูปหัวข้อเรียน!E:G,3,FALSE)) -> https://drive.google.com/file/d/11SiQpgue7bTguuuF-WXlkRC_KpeN0KU1/view?usp=drivesdk
A33: =A32+1 -> 15 | B33: ประวัติอาจารย์ | D33: =TRIM(B10) -> 1.2.01 | E33: =B15 -> อ.วรรณา ลิ่มพานิชย์ | F33: #NAME? | G33: =HYPERLINK(VLOOKUP(D33,linkรูปอาจารย์!E:G,3,FALSE)) -> https://drive.google.com/file/d/1yaG809Lyzt_OdF0Iv4lcZmuL7Ow5CHmu/view?usp=drivesdk
A34: =A33+1 -> 16 | B34: =D34 -> วันพุธที่ 13 พ.ย. 67 หัวข้อ 1.2.01 ความตั้งใจ เทปทบทวนการบรรยาย: อ.วรรณา ลิ่มพานิชย์ https://youtu.be/DnHVtsJ8xVw | D34: =$B$8& CHAR(10) &"หัวข้อ " & $B$9 & CHAR(10) &"เทปทบทวนการบรรยาย:" &CHAR(10) & B15 &CHAR(10) &CHAR(10) &B14 -> วันพุธที่ 13 พ.ย. 67 หัวข้อ 1.2.01 ความตั้งใจ เทปทบทวนการบรรยาย: อ.วรรณา ลิ่มพานิชย์ https://youtu.be/DnHVtsJ8xVw | E34: =B13 -> 13:44 | F34: =D34 -> วันพุธที่ 13 พ.ย. 67 หัวข้อ 1.2.01 ความตั้งใจ เทปทบทวนการบรรยาย: อ.วรรณา ลิ่มพานิชย์ https://youtu.be/DnHVtsJ8xVw | G34: =HYPERLINK(B14) -> https://youtu.be/DnHVtsJ8xVw | H34: #NAME?
A35: =A34+1 -> 17 | B35: =D35 -> * เวลา 18:51 น. โพสต์ | D35: ="* เวลา "&TEXT(E35,"hh:mm")&" น. โพสต์" -> * เวลา 18:51 น. โพสต์ | E35: =TIME(LEFT(TEXT(E30,"hh:mm"),2),RIGHT(TEXT(E30,"hh:mm"),2),0)+IF(INT(RIGHT(E34,2))>0,TIME(0,LEFT(E34,2)+1,0),TIME(0,LEFT(E34,2),0)) -> 0.78541667 | F35: =D35 -> * เวลา 18:51 น. โพสต์
A36: =A35+1 -> 18 | B36: =D36 -> ขอเชิญนักศึกษาทุกท่านปฏิบัติเดินจงกรม เป็นเวลา 30 นาที https://youtu.be/jHQ_63bROqY | D36: ขอเชิญนักศึกษาทุกท่านปฏิบัติเดินจงกรม เป็นเวลา 30 นาที https://youtu.be/jHQ_63bROqY | E36: 32.00 | F36: =D36 -> ขอเชิญนักศึกษาทุกท่านปฏิบัติเดินจงกรม เป็นเวลา 30 นาที https://youtu.be/jHQ_63bROqY | G36: https://youtu.be/jHQ_63bROqY | H36: #NAME?
A37: =A36+1 -> 19 | B37: =D37 -> * เวลา 19:23 น. โพสต์ | D37: ="* เวลา "&TEXT(E37,"hh:mm")&" น. โพสต์" -> * เวลา 19:23 น. โพสต์ | E37: =TIME(LEFT(TEXT(E35,"hh:mm"),2),RIGHT(TEXT(E35,"hh:mm"),2),0)+IF(INT(RIGHT(E36,2))>0,TIME(0,LEFT(E36,2)+1,0),TIME(0,LEFT(E36,2),0)) -> 0.80763889 | F37: =D37 -> * เวลา 19:23 น. โพสต์
A38: =A37+1 -> 20 | B38: =D38 -> ขอเชิญนักศึกษาทุกท่านปฏิบัตินั่งสมาธิ เป็นเวลา 30 นาที https://youtu.be/hiZ16DCP1eI | D38: ขอเชิญนักศึกษาทุกท่านปฏิบัตินั่งสมาธิ เป็นเวลา 30 นาที https://youtu.be/hiZ16DCP1eI | E38: 33.00 | F38: =D38 -> ขอเชิญนักศึกษาทุกท่านปฏิบัตินั่งสมาธิ เป็นเวลา 30 นาที https://youtu.be/hiZ16DCP1eI | G38: https://youtu.be/hiZ16DCP1eI | H38: #NAME?
A39: =A38+1 -> 21 | B39: =D39 -> * เวลา 19:56 น. โพสต์ | D39: ="* เวลา "&TEXT(E39,"hh:mm")&" น. โพสต์" -> * เวลา 19:56 น. โพสต์ | E39: =TIME(LEFT(TEXT(E37,"hh:mm"),2),RIGHT(TEXT(E37,"hh:mm"),2),0)+IF(INT(RIGHT(E38,2))>0,TIME(0,LEFT(E38,2)+1,0),TIME(0,LEFT(E38,2),0)) -> 0.83055556 | F39: =D39 -> * เวลา 19:56 น. โพสต์
A40: =A39+1 -> 22 | B40: =D40 -> ขอเชิญนักศึกษาทุกท่านร่วมบูชาพระรัตนตรัย โดยพร้อมเพรียงกัน https://youtu.be/viTRlM3Xme4 | D40: ขอเชิญนักศึกษาทุกท่านร่วมบูชาพระรัตนตรัย โดยพร้อมเพรียงกัน https://youtu.be/viTRlM3Xme4 | E40: 2.00 | F40: =D40 -> ขอเชิญนักศึกษาทุกท่านร่วมบูชาพระรัตนตรัย โดยพร้อมเพรียงกัน https://youtu.be/viTRlM3Xme4 | G40: https://youtu.be/viTRlM3Xme4 | H40: #NAME?
A41: =A40+1 -> 23 | B41: =D41 -> * เวลา 19:58 น. โพสต์ | D41: ="* เวลา "&TEXT(E41,"hh:mm")&" น. โพสต์" -> * เวลา 19:58 น. โพสต์ | E41: =TIME(LEFT(TEXT(E39,"hh:mm"),2),RIGHT(TEXT(E39,"hh:mm"),2),0)+IF(INT(RIGHT(E40,2))>0,TIME(0,LEFT(E40,2)+1,0),TIME(0,LEFT(E40,2),0)) -> 0.83194444 | F41: =D41 -> * เวลา 19:58 น. โพสต์
A42: =A41+1 -> 24 | B42: การเรียนครั้งต่อไป | C42: สไลด์เรียนประจำวัน | D42: =TRIM($B$10)&"-Slide3.JPG" -> 1.2.01-Slide3.JPG | E42: 00.00 | F42: #NAME? | G42: =HYPERLINK(VLOOKUP(D42,linkรูปหัวข้อเรียน!E:G,3,FALSE)) -> https://drive.google.com/file/d/1evHCxONLKQw6aLhkPB0-DivKVilowsSi/view?usp=drivesdk
...

Sheet linkเรียนประจำวัน
A1: ลำดับ | B1: Folder Path | C1: หัวข้อ | D1: Filename | E1: Key | F1: รูป | G1: Image Link | H1: หมายเหตุ
A2: 1 | B2: 5 สไลด์เรียนประจำวัน (ล่าสุด) | C2: เรียนประจำวัน | D2: Slide1.JPG | E2: =TRIM(C2&"-"&D2) -> เรียนประจำวัน-Slide1.JPG | F2: #NAME? | G2: https://drive.google.com/file/d/1qEFjPE12L0OST-IfMwE0TqLEAok_Gj_Y/view?usp=drivesdk
A3: =A2+1 -> 2 | B3: 5 สไลด์เรียนประจำวัน (ล่าสุด) | C3: เรียนประจำวัน | D3: Slide2.JPG | E3: =TRIM(C3&"-"&D3) -> เรียนประจำวัน-Slide2.JPG | F3: #NAME? | G3: https://drive.google.com/file/d/1fRZwcyO1bupTd_ZP73mlu2IJOa5sl0lO/view?usp=drivesdk
A4: =A3+1 -> 3 | B4: 5 สไลด์เรียนประจำวัน (ล่าสุด) | C4: เรียนประจำวัน | D4: Slide3.JPG | E4: =TRIM(C4&"-"&D4) -> เรียนประจำวัน-Slide3.JPG | F4: #NAME? | G4: https://drive.google.com/file/d/1CM_L3MeD8EtenRkSS7A7m9HJ9ahiw95a/view?usp=drivesdk | H4: ต้องเปลี่ยนทุกวัน
A5: =A4+1 -> 4 | B5: 5 สไลด์เรียนประจำวัน (ล่าสุด) | C5: เรียนประจำวัน | D5: Slide4.JPG | E5: =TRIM(C5&"-"&D5) -> เรียนประจำวัน-Slide4.JPG | F5: #NAME? | G5: https://drive.google.com/file/d/1OJ5AltlO515XLHsEvLzcZqzf5DJzpgmd/view?usp=drivesdk
A6: =A5+1 -> 5 | B6: 5 สไลด์เรียนประจำวัน (ล่าสุด) | C6: เรียนประจำวัน | D6: Slide5.JPG | E6: =TRIM(C6&"-"&D6) -> เรียนประจำวัน-Slide5.JPG | F6: #NAME? | G6: https://drive.google.com/file/d/1wWIqRH1hCNEvrHpdUvwkQC8TXbzb6S4z/view?usp=drivesdk
A7: =A6+1 -> 6 | B7: 5 สไลด์เรียนประจำวัน (ล่าสุด) | C7: เรียนประจำวัน | D7: Slide6.JPG | E7: =TRIM(C7&"-"&D7) -> เรียนประจำวัน-Slide6.JPG | F7: #NAME? | G7: https://drive.google.com/file/d/15vLqd04idYXVvoz_QT_eKE12MhDkHgaW/view?usp=drivesdk | H7: ต้องเปลี่ยนทุกวัน

Sheet linkรูปหัวข้อเรียน
A1: Group | B1: Folder Path | C1: เลขหัวข้อ | D1: Filename | E1: Key | F1: รูป | G1: Image Link
A2: 1 | B2: /หัวข้อเรียน 1.1/หัวข้อเรียน 1.1.01 | C2: 1.1.01 | D2: Slide1.JPG | E2: =TRIM(C2&"-"&D2) -> 1.1.01-Slide1.JPG | F2: #NAME? | G2: https://drive.google.com/file/d/1abW-oMOXpS3s_4GdVvCOTFNC9K-wfmqT/view?usp=drivesdk
A3: 1 | B3: /หัวข้อเรียน 1.1/หัวข้อเรียน 1.1.01 | C3: 1.1.01 | D3: Slide2.JPG | E3: =TRIM(C3&"-"&D3) -> 1.1.01-Slide2.JPG | F3: #NAME? | G3: https://drive.google.com/file/d/1Z6n4BfaAPY4EUeOnNE-9M4dXMgytcZhw/view?usp=drivesdk
A4: 1 | B4: /หัวข้อเรียน 1.1/หัวข้อเรียน 1.1.01 | C4: 1.1.01 | D4: Slide3.JPG | E4: =TRIM(C4&"-"&D4) -> 1.1.01-Slide3.JPG | F4: #NAME? | G4: https://drive.google.com/file/d/1QWm8i65OZuKFx4So-pEMYfci4t8G4MZU/view?usp=drivesdk
A5: 1 | B5: /หัวข้อเรียน 1.1/หัวข้อเรียน 1.1.02 | C5: 1.1.02 | D5: Slide1.JPG | E5: =TRIM(C5&"-"&D5) -> 1.1.02-Slide1.JPG | F5: #NAME? | G5: https://drive.google.com/file/d/1hwOl_Hne9f4SQKv4_zRBORIqqccR_SGF/view?usp=drivesdk
A6: 1 | B6: /หัวข้อเรียน 1.1/หัวข้อเรียน 1.1.02 | C6: 1.1.02 | D6: Slide2.JPG | E6: =TRIM(C6&"-"&D6) -> 1.1.02-Slide2.JPG | F6: #NAME? | G6: https://drive.google.com/file/d/1vUtDHU42cfX-JREUwIXFQ14iWmIiZIin/view?usp=drivesdk
A7: 1 | B7: /หัวข้อเรียน 1.1/หัวข้อเรียน 1.1.02 | C7: 1.1.02 | D7: Slide3.JPG | E7: =TRIM(C7&"-"&D7) -> 1.1.02-Slide3.JPG | F7: #NAME? | G7: https://drive.google.com/file/d/1i0En2iEj723IhVjQ-bVITTBpRwReDgL-/view?usp=drivesdk
A8: 1 | B8: /หัวข้อเรียน 1.1/หัวข้อเรียน 1.1.03 | C8: 1.1.03 | D8: Slide1.JPG | E8: =TRIM(C8&"-"&D8) -> 1.1.03-Slide1.JPG | F8: #NAME? | G8: https://drive.google.com/file/d/1_V7XPkVDbOOoJX_L_Ihu6CEaVxraDsB_/view?usp=drivesdk
A9: 1 | B9: /หัวข้อเรียน 1.1/หัวข้อเรียน 1.1.03 | C9: 1.1.03 | D9: Slide2.JPG | E9: =TRIM(C9&"-"&D9) -> 1.1.03-Slide2.JPG | F9: #NAME? | G9: https://drive.google.com/file/d/1dqVOX3B9DtgFU2e2rNMYRU3uLa7SfqUm/view?usp=drivesdk
A10: 1 | B10: /หัวข้อเรียน 1.1/หัวข้อเรียน 1.1.03 | C10: 1.1.03 | D10: Slide3.JPG | E10: =TRIM(C10&"-"&D10) -> 1.1.03-Slide3.JPG | F10: #NAME? | G10: https://drive.google.com/file/d/1idaBNGmzJpwld9AsQqoiWGBoiYTUWuNi/view?usp=drivesdk
A11: 1 | B11: /หัวข้อเรียน 1.1/หัวข้อเรียน 1.1.04 | C11: 1.1.04 | D11: Slide1.JPG | E11: =TRIM(C11&"-"&D11) -> 1.1.04-Slide1.JPG | F11: #NAME? | G11: https://drive.google.com/file/d/1ENQKVJibb7I3PT-mu-xXQBM44I9cDu7o/view?usp=drivesdk
A12: 1 | B12: /หัวข้อเรียน 1.1/หัวข้อเรียน 1.1.04 | C12: 1.1.04 | D12: Slide2.JPG | E12: =TRIM(C12&"-"&D12) -> 1.1.04-Slide2.JPG | F12: #NAME? | G12: https://drive.google.com/file/d/107-KMuYq5-sQW_eMlKvFwWrHDpKdMQiT/view?usp=drivesdk
A13: 1 | B13: /หัวข้อเรียน 1.1/หัวข้อเรียน 1.1.04 | C13: 1.1.04 | D13: Slide3.JPG | E13: =TRIM(C13&"-"&D13) -> 1.1.04-Slide3.JPG | F13: #NAME? | G13: https://drive.google.com/file/d/1hDrmWJbFBGK52uMoLJiBTycNxyg62w5Z/view?usp=drivesdk
... A286: 1 | B286: /หัวข้อเรียน 3.2/หัวข้อเรียน 3.2.09 | C286: 3.2.09 | D286: Slide3.JPG | E286: =TRIM(C286&"-"&D286) -> 3.2.09-Slide3.JPG | F286: #NAME? | G286: https://drive.google.com/file/d/1_yBFSp0oX8T3taTI4OCNoiZPcA5qRfV6/view?usp=drivesdk
A287: 2 | B287: /บันทึกบทท้าย เทอม 1 (เพิ่มลิขสิทธิ์) | D287: Slide1.JPG | E287: =TRIM(C287&"-"&D287) -> -Slide1.JPG | F287: #NAME? | G287: https://drive.google.com/file/d/1xncsZlSemoASmree2vx3gNI0-e03lKl_/view?usp=drivesdk
A288: 2 | B288: /บันทึกบทท้าย เทอม 1 (เพิ่มลิขสิทธิ์) | D288: Slide10.JPG | E288: =TRIM(C288&"-"&D288) -> -Slide10.JPG | F288: #NAME? | G288: https://drive.google.com/file/d/17p2BpFnM_Lw1AH-vVC3NULZlVu34dAPW/view?usp=drivesdk
A289: 2 | B289: /บันทึกบทท้าย เทอม 1 (เพิ่มลิขสิทธิ์) | D289: Slide11.JPG | E289: =TRIM(C289&"-"&D289) -> -Slide11.JPG | F289: #NAME? | G289: https://drive.google.com/file/d/1cUvwou27LgMj0Cj_makLW1PbHhbhkNfZ/view?usp=drivesdk
A290: 2 | B290: /บันทึกบทท้าย เทอม 1 (เพิ่มลิขสิทธิ์) | D290: Slide12.JPG | E290: =TRIM(C290&"-"&D290) -> -Slide12.JPG | F290: #NAME? | G290: https://drive.google.com/file/d/1FoAuFbiw52ogLQ4cuRXgppCyQdL0nhse/view?usp=drivesdk
A291: 2 | B291: /บันทึกบทท้าย เทอม 1 (เพิ่มลิขสิทธิ์) | D291: Slide13.JPG | E291: =TRIM(C291&"-"&D291) -> -Slide13.JPG | F291: #NAME? | G291: https://drive.google.com/file/d/1cloGOjB1J0n4tMzZpc8tKDR3gsx04_uE/view?usp=drivesdk
A292: 2 | B292: /บันทึกบทท้าย เทอม 1 (เพิ่มลิขสิทธิ์) | D292: Slide14.jpg | E292: =TRIM(C292&"-"&D292) -> -Slide14.jpg | F292: #NAME? | G292: https://drive.google.com/file/d/1k_6A2razrlfqKxwqNYy4i1Z_R7ZJacNL/view?usp=drivesdk
A293: 2 | B293: /บันทึกบทท้าย เทอม 1 (เพิ่มลิขสิทธิ์) | D293: Slide15.JPG | E293: =TRIM(C293&"-"&D293) -> -Slide15.JPG | F293: #NAME? | G293: https://drive.google.com/file/d/1eg1V7rZ-t1LWDz97W60yuw2hX6rb8uir/view?usp=drivesdk
A294: 2 | B294: /บันทึกบทท้าย เทอม 1 (เพิ่มลิขสิทธิ์) | D294: Slide16.JPG | E294: =TRIM(C294&"-"&D294) -> -Slide16.JPG | F294: #NAME? | G294: https://drive.google.com/file/d/1f_yslGCG4xBupHPNWbTV3DzHzJSWi2pE/view?usp=drivesdk
A295: 2 | B295: /บันทึกบทท้าย เทอม 1 (เพิ่มลิขสิทธิ์) | D295: Slide17.jpg | E295: =TRIM(C295&"-"&D295) -> -Slide17.jpg | F295: #NAME? | G295: https://drive.google.com/file/d/1-9_9qObiyUlBhAuuPRCJczREc8_RNH4m/view?usp=drivesdk
A296: 2 | B296: /บันทึกบทท้าย เทอม 1 (เพิ่มลิขสิทธิ์) | D296: Slide18.JPG | E296: =TRIM(C296&"-"&D296) -> -Slide18.JPG | F296: #NAME? | G296: https://drive.google.com/file/d/1_Z_zoNqqdqzDewdH4eivHT5H1JOLUo2C/view?usp=drivesdk
A297: 2 | B297: /บันทึกบทท้าย เทอม 1 (เพิ่มลิขสิทธิ์) | D297: Slide19.JPG | E297: =TRIM(C297&"-"&D297) -> -Slide19.JPG | F297: #NAME? | G297: https://drive.google.com/file/d/1RRqQ08Bwd8EHOe83YcJ09eHKNzeGGfvi/view?usp=drivesdk
A298: 2 | B298: /บันทึกบทท้าย เทอม 1 (เพิ่มลิขสิทธิ์) | D298: Slide2.JPG | E298: =TRIM(C298&"-"&D298) -> -Slide2.JPG | F298: #NAME? | G298: https://drive.google.com/file/d/1Bi_b22d3pRCQWm-sXxO05p6WZe4uP7-9/view?usp=drivesdk
... A318: 2 | B318: /บันทึกบทท้าย เทอม 1 (เพิ่มลิขสิทธิ์) | D318: Slide9.JPG | E318: =TRIM(C318&"-"&D318) -> -Slide9.JPG | F318: #NAME? | G318: https://drive.google.com/file/d/1092Hy_VNidcXMKswUkTZ4hKMjZ0qNGJT/view?usp=drivesdk

Sheet linkรูปอาจารย์
A1: ลำดับ | B1: Folder Path | C1: หัวข้อ | D1: Filename | E1: key | F1: รูป | G1: Image Link
A2: 1 | B2: 7 สไลด์ประวัติอาจารย์/หัวข้อ 1.1 | C2: สไลด์ประวัติอาจารย์ | D2: 1.1.00_ดร.บวรศักดิ์ อุวรรณโณ.jpg | E2: =TRIM(LEFT(D2,FIND("_",D2)-1)) -> 1.1.00 | F2: #NAME? | G2: https://drive.google.com/file/d/1iOFQuug_vDF6Ffs0d-kLITK40CfugfDc/view?usp=drivesdk
A3: =A2+1 -> 2 | B3: 7 สไลด์ประวัติอาจารย์/หัวข้อ 1.1 | C3: สไลด์ประวัติอาจารย์ | D3: 1.1.01_อ.เรณุกา พันทวีศักดิ์.jpg | E3: =TRIM(LEFT(D3,FIND("_",D3)-1)) -> 1.1.01 | F3: #NAME? | G3: https://drive.google.com/file/d/1RLQLeQbNTu4IyNUA7svWCIXiOXc3YI8v/view?usp=drivesdk
A4: =A3+1 -> 3 | B4: 7 สไลด์ประวัติอาจารย์/หัวข้อ 1.1 | C4: สไลด์ประวัติอาจารย์ | D4: 1.1.02_อ.แสงอรุณ วัฒนวงศ์.jpg | E4: =TRIM(LEFT(D4,FIND("_",D4)-1)) -> 1.1.02 | F4: #NAME? | G4: https://drive.google.com/file/d/1LQzApZp5mUwNlL-hjGyYBe2buXct-39X/view?usp=drivesdk
A5: =A4+1 -> 4 | B5: 7 สไลด์ประวัติอาจารย์/หัวข้อ 1.1 | C5: สไลด์ประวัติอาจารย์ | D5: 1.1.03_อ.ศรีวิมล ฉัตรจุฑามาส.jpg | E5: =TRIM(LEFT(D5,FIND("_",D5)-1)) -> 1.1.03 | F5: #NAME? | G5: https://drive.google.com/file/d/1XsNCE7-Wpb1tjkfFimvEvAeLdcWRQpCz/view?usp=drivesdk
A6: =A5+1 -> 5 | B6: 7 สไลด์ประวัติอาจารย์/หัวข้อ 1.1 | C6: สไลด์ประวัติอาจารย์ | D6: 1.1.04_อ.สิริกร สุขเกษม.jpeg | E6: =TRIM(LEFT(D6,FIND("_",D6)-1)) -> 1.1.04 | F6: #NAME? | G6: https://drive.google.com/file/d/1hV2Fd_-Wme7DW-2ZYxul86eSeeY85DUG/view?usp=drivesdk
A7: =A6+1 -> 6 | B7: 7 สไลด์ประวัติอาจารย์/หัวข้อ 1.1 | C7: สไลด์ประวัติอาจารย์ | D7: 1.1.05_รศ.ธิติ รักชาติ.jpg | E7: =TRIM(LEFT(D7,FIND("_",D7)-1)) -> 1.1.05 | F7: #NAME? | G7: https://drive.google.com/file/d/11PRs3tA1R_qB_gIDHCwswea2vb5wEJ9i/view?usp=drivesdk
A8: =A7+1 -> 7 | B8: 7 สไลด์ประวัติอาจารย์/หัวข้อ 1.1 | C8: สไลด์ประวัติอาจารย์ | D8: 1.1.06_อ.พรรณี จารุสมบัติ.jpg | E8: =TRIM(LEFT(D8,FIND("_",D8)-1)) -> 1.1.06 | F8: #NAME? | G8: https://drive.google.com/file/d/1XlKgc68z8dBpUjFn1CiLG5IRQL8KDb0F/view?usp=drivesdk
A9: =A8+1 -> 8 | B9: 7 สไลด์ประวัติอาจารย์/หัวข้อ 1.2 | C9: สไลด์ประวัติอาจารย์ | D9: 1.2.01_อ.วรรณา ลิ่่มพานิช.jpeg | E9: =TRIM(LEFT(D9,FIND("_",D9)-1)) -> 1.2.01 | F9: #NAME? | G9: https://drive.google.com/file/d/1yaG809Lyzt_OdF0Iv4lcZmuL7Ow5CHmu/view?usp=drivesdk
A10: =A9+1 -> 9 | B10: 7 สไลด์ประวัติอาจารย์/หัวข้อ 1.2 | C10: สไลด์ประวัติอาจารย์ | D10: 1.2.02_ดร.ปฐมพงษ์ โพธิ์ประสิทธินันท์.jpeg | E10: =TRIM(LEFT(D10,FIND("_",D10)-1)) -> 1.2.02 | F10: #NAME? | G10: https://drive.google.com/file/d/1hl1-VUjTp0kK8LIi99ywEgJNdx-b0JXO/view?usp=drivesdk
A11: =A10+1 -> 10 | B11: 7 สไลด์ประวัติอาจารย์/หัวข้อ 1.2 | C11: สไลด์ประวัติอาจารย์ | D11: 1.2.03_ดร.ดาวน้อย สุทธินิภาพันธ์.jpeg | E11: =TRIM(LEFT(D11,FIND("_",D11)-1)) -> 1.2.03 | F11: #NAME? | G11: https://drive.google.com/file/d/1WtIbRcAW0ZApJJ0VKjT07CwGhUWz4hJa/view?usp=drivesdk
A12: =A11+1 -> 11 | B12: 7 สไลด์ประวัติอาจารย์/หัวข้อ 1.2 | C12: สไลด์ประวัติอาจารย์ | D12: 1.2.04_อ.สุดารักษ์ ยิ่งสกุล.jpeg | E12: =TRIM(LEFT(D12,FIND("_",D12)-1)) -> 1.2.04 | F12: #NAME? | G12: https://drive.google.com/file/d/1ChkS8axMRFC_H9BVchSeSya4JLRhcn81/view?usp=drivesdk
A13: =A12+1 -> 12 | B13: 7 สไลด์ประวัติอาจารย์/หัวข้อ 1.2 | C13: สไลด์ประวัติอาจารย์ | D13: 1.2.05_รศ.ภณิดา มาประเสริฐ.jpeg | E13: =TRIM(LEFT(D13,FIND("_",D13)-1)) -> 1.2.05 | F13: #NAME? | G13: https://drive.google.com/file/d/1-S4pk-a10-O_-Buk1njhw_dkupDlu7UX/view?usp=drivesdk
A14: =A13+1 -> 13 | B14: 7 สไลด์ประวัติอาจารย์/หัวข้อ 1.2 | C14: สไลด์ประวัติอาจารย์ | D14: 1.2.06_อ.สุนทรี งามเลิศ.jpeg | E14: =TRIM(LEFT(D14,FIND("_",D14)-1)) -> 1.2.06 | F14: #NAME? | G14: https://drive.google.com/file/d/1LjwQxKEvpSVbb5QIUWbmD22zSnD6g_VK/view?usp=drivesdk
... A24: =A23+1 -> 23 | B24: 7 สไลด์ประวัติอาจารย์/หัวข้อ 1.3 | C24: สไลด์ประวัติอาจารย์ | D24: 1.3.08_อ.สาธิตา ชูติกาญจน์.jpg | E24: =TRIM(LEFT(D24,FIND("_",D24)-1)) -> 1.3.08 | F24: #NAME? | G24: https://drive.google.com/file/d/1LfdCmnmR0z-cBKds34gwSlbARcEdUZp8/view?usp=drivesdk
A25: 1 | B25: 7 สไลด์ประวัติอาจารย์/หัวข้อ 1.4 | C25: สไลด์ประวัติอาจารย์ | D25: 1.4.01_อ.ประพีร์ บุรี.jpg | E25: =TRIM(LEFT(D25,FIND("_",D25)-1)) -> 1.4.01 | F25: #NAME? | G25: https://drive.google.com/file/d/1YP9UrifeK3SEs0siX-ACdUpn7iERz6tf/view?usp=drivesdk
A26: =A25+1 -> 2 | B26: 7 สไลด์ประวัติอาจารย์/หัวข้อ 1.4 | C26: สไลด์ประวัติอาจารย์ | D26: 1.4.02_ดร.ธเนศ วีระศิริ.jpg | E26: =TRIM(LEFT(D26,FIND("_",D26)-1)) -> 1.4.02 | F26: #NAME? | G26: https://drive.google.com/file/d/1Oh0k-DVdKu1IKTku3GNbpik7AeJ9r-96/view?usp=drivesdk
A27: =A26+1 -> 3 | B27: 7 สไลด์ประวัติอาจารย์/หัวข้อ 1.4 | C27: สไลด์ประวัติอาจารย์ | D27: 1.4.03_ดร.ธีรวัฒนา ภาระมาตย์.jpg | E27: =TRIM(LEFT(D27,FIND("_",D27)-1)) -> 1.4.03 | F27: #NAME? | G27: https://drive.google.com/file/d/1QFDqp7CyZ5RhcKeXYnRGovG9ZnrldLZH/view?usp=drivesdk
A28: =A27+1 -> 4 | B28: 7 สไลด์ประวัติอาจารย์/หัวข้อ 1.4 | C28: สไลด์ประวัติอาจารย์ | D28: 1.4.04_อ.จุไร วรศักดิ์โยธิน.jpg | E28: =TRIM(LEFT(D28,FIND("_",D28)-1)) -> 1.4.04 | F28: #NAME? | G28: https://drive.google.com/file/d/10ePntmhYRxY8nFSqlg4KEmpN-dpMn_lS/view?usp=drivesdk
A29: =A28+1 -> 5 | B29: 7 สไลด์ประวัติอาจารย์/หัวข้อ 1.4 | C29: สไลด์ประวัติอาจารย์ | D29: 1.4.05_อ.ปัทมาภรณ์ มิกานนท์.jpg | E29: =TRIM(LEFT(D29,FIND("_",D29)-1)) -> 1.4.05 | F29: #NAME? | G29: https://drive.google.com/file/d/1dmM1Lqqu2WSteChLglJ_fMLCZjr-GVE7/view?usp=drivesdk
A30: =A29+1 -> 6 | B30: 7 สไลด์ประวัติอาจารย์/หัวข้อ 1.4 | C30: สไลด์ประวัติอาจารย์ | D30: 1.4.06_พญ.ปณดา อัศวเคนทร์กุล.jpg | E30: =TRIM(LEFT(D30,FIND("_",D30)-1)) -> 1.4.06 | F30: #NAME? | G30: https://drive.google.com/file/d/1XuJocdSScITbEQgO_J0LADJ1Vn1fJcUR/view?usp=drivesdk
A31: =A30+1 -> 7 | B31: 7 สไลด์ประวัติอาจารย์/หัวข้อ 1.4 | C31: สไลด์ประวัติอาจารย์ | D31: 1.4.07_อ.ทรงศิริ จุมพล.jpg | E31: =TRIM(LEFT(D31,FIND("_",D31)-1)) -> 1.4.07 | F31: #NAME? | G31: https://drive.google.com/file/d/1U6FhF18sV817MBW3jQ5q8k_BOQ_GFkaO/view?usp=drivesdk
A32: =A31+1 -> 8 | B32: 7 สไลด์ประวัติอาจารย์/หัวข้อ 2.1 | C32: สไลด์ประวัติอาจารย์ | D32: 2.1.01_ผศ.พรทิพย์ รักชาติ.jpg | E32: =TRIM(LEFT(D32,FIND("_",D32)-1)) -> 2.1.01 | F32: #NAME? | G32: https://drive.google.com/file/d/1IP7pQ3R9aw_yrFTXy_1-2hOhowivJ92m/view?usp=drivesdk
A33: =A32+1 -> 9 | B33: 7 สไลด์ประวัติอาจารย์/หัวข้อ 2.1 | C33: สไลด์ประวัติอาจารย์ | D33: 2.1.02_อ.วรเดช กล่อมจันทร์.jpg | E33: =TRIM(LEFT(D33,FIND("_",D33)-1)) -> 2.1.02 | F33: #NAME? | G33: https://drive.google.com/file/d/1WlCIQ8KCgUYbD7_r_8qj2huo8F-OSQFM/view?usp=drivesdk
A34: =A33+1 -> 10 | B34: 7 สไลด์ประวัติอาจารย์/หัวข้อ 2.1 | C34: สไลด์ประวัติอาจารย์ | D34: 2.1.03_อ.สมพร สะราคำ.jpg | E34: =TRIM(LEFT(D34,FIND("_",D34)-1)) -> 2.1.03 | F34: #NAME? | G34: https://drive.google.com/file/d/1dpErMe5CkTkGKhSVPdt8V48dzEwCU8xf/view?usp=drivesdk
A35: =A34+1 -> 11 | B35: 7 สไลด์ประวัติอาจารย์/หัวข้อ 2.1 | C35: สไลด์ประวัติอาจารย์ | D35: 2.1.04_อ.อุมาลี อยู่นันท์.jpg | E35: =TRIM(LEFT(D35,FIND("_",D35)-1)) -> 2.1.04 | F35: #NAME? | G35: https://drive.google.com/file/d/14hYspjR2lbjocXhfbA6VxsWsvhSCih-O/view?usp=drivesdk
A36: =A35+1 -> 12 | B36: 7 สไลด์ประวัติอาจารย์/หัวข้อ 2.1 | C36: สไลด์ประวัติอาจารย์ | D36: 2.1.05_รศ.กัลยาภรณ์ ปานมะเริง.jpg | E36: =TRIM(LEFT(D36,FIND("_",D36)-1)) -> 2.1.05 | F36: #NAME? | G36: https://drive.google.com/file/d/1V5TRl2nuJtU3spX9q9nQUkwnwuiOQKPx/view?usp=drivesdk
A37: =A36+1 -> 13 | B37: 7 สไลด์ประวัติอาจารย์/หัวข้อ 2.1 | C37: สไลด์ประวัติอาจารย์ | D37: 2.1.06_อ.วัชรี วัฒนาสุทธิวงศ์.jpg | E37: =TRIM(LEFT(D37,FIND("_",D37)-1)) -> 2.1.06 | F37: #NAME? | G37: https://drive.google.com/file/d/1AoKG8gXXxMejwd4ikBTepv0ELPumf12u/view?usp=drivesdk
... A99: =A98+1 -> 75 | B99: 7 สไลด์ประวัติอาจารย์/หัวข้อบทท้าย เทอม1-2 | C99: สไลด์ประวัติอาจารย์ | D99: บันทึกท้ายบท เทอมที่ 1_ดร.ดาวน้อย สุทธินิภาพันธ์.jpg | E99: =TRIM(LEFT(D99,FIND("_",D99)-1)) -> บันทึกท้ายบท เทอมที่ 1 | F99: #NAME? | G99: https://drive.google.com/file/d/1YK6TgaMtgu3HC6647RU--glimL-yWPuL/view?usp=drivesdk
